Workbook

Sheet Case
A1: Production Budget, Material Planning & Commodity Price Risk Analysis
A3: AluWrap Industries Ltd. - Business Scenario
A5: AluWrap Industries Ltd. is a leading manufacturer of household and commercial aluminium foil products supplied to supermarkets, food packaging companies, hotels, restaurants, and pharmaceutical manufacturers across India.
A6: The company operates a centralized manufacturing facility where aluminium foil rolls are produced based on customer demand forecasts prepared by the Sales and Marketing team.
A7: The FY2027 Sales Budget has already been finalized and approved by management. Based on the approved sales forecast, the Operations, Procurement, and FP&A teams must now prepare the detailed production
A8: and material procurement plans to ensure uninterrupted manufacturing while maintaining optimal inventory levels.
A9: Aluminium is the company's most significant raw material, accounting for approximately 85% of the total raw material cost.
A10: Since aluminium prices are linked to international commodity markets and are subject to significant volatility, fluctuations in prices can materially impact production costs, gross margins, and overall profitability.
A11: To support the budgeting process, the FP&A team has obtained 36 months of historical aluminium prices (USD per metric tonne) based on London Metal Exchange (LME) market prices.
A12: Management expects the FP&A team to analyze historical price movements, identify pricing trends, evaluate commodity price volatility, and recommend an appropriate budget price for FY2027 procurement planning.
A13: In addition, the Treasury team has proposed evaluating a commodity hedging strategy using aluminium futures to mitigate the impact of adverse price movements.
A14: They hedge for the next month purchase at current month and purchases are placed with supplier on start of month for the entire requirement
... A46: Present operational and financial insights through an executive management dashboard.

Sheet Approved SB & Assumptions
A1: Approved Sales Budget and Other Assumptions
A4: Month | B4: Budgeted Sales (Rolls) | C4: Selling Price/Unit (USD) | D4: Sales Revenue (USD) | F4: Particulars | G4: Assumption
A5: April | B5: 120000 | C5: 4.5 | D5: 540000 | F5: Product | G5: Household Aluminium Foil Roll (30 cm × 18 m)
A6: May | B6: 125000 | C6: 4.5 | D6: 562500 | F6: Financial Year | G6: FY2027 (April 2026 – March 2027)
A7: June | B7: 130000 | C7: 4.5 | D7: 585000 | F7: Approved Annual Sales Volume | G7: 1,800,000 Rolls
A8: July | B8: 135000 | C8: 4.6 | D8: 621000 | F8: Opening Finished Goods Inventory | G8: 12,000 Rolls
A9: August | B9: 140000 | C9: 4.6 | D9: 644000 | F9: Closing FG | G9: 10% of Next Month's Budgeted Sales
A10: September | B10: 145000 | C10: 4.6 | D10: 667000 | F10: Aluminium Consumption per Roll | G10: 0.38 kg
A11: October | B11: 155000 | C11: 4.7 | D11: 728500 | F11: Normal Production Loss | G11: 2% of Aluminium Consumption
A12: November | B12: 165000 | C12: 4.7 | D12: 775500 | F12: Opening Aluminium Inventory | G12: 8,000 kg
A13: December | B13: 180000 | C13: 4.8 | D13: 864000 | F13: Closing RM | G13: 15% of Next Month's Aluminium Requirement
A14: January | B14: 170000 | C14: 4.8 | D14: 816000 | F14: Hedging Instrument | G14: Aluminium Futures
A15: February | B15: 160000 | C15: 4.8 | D15: 768000 | F15: Proposed Hedge Coverage | G15: 100% of Aluminium Purchases
A16: March | B16: 175000 | C16: 4.9 | D16: 857500 | F16: Production Capacity | G16: 200,000 Rolls per Month
A17: Total | B17: 1800000 | C17: - | D17: 8429000

Sheet Production Budget
A1: Production Budget
A4: Particulars | B4: Apr | C4: May | D4: Jun | E4: Jul | F4: Aug | G4: Sep | H4: Oct | I4: Nov | J4: Dec | K4: Jan | L4: Feb | M4: Mar
A5: Budgeted Sales (Units) | B5: 120000 | C5: 125000 | D5: 130000 | E5: 135000 | F5: 140000 | G5: 145000 | H5: 155000 | I5: 165000 | J5: 180000 | K5: 170000 | L5: 160000 | M5: 175000
A6: Add: Desired Closing FG Inventory | B6: =C5*10% -> 12500 | C6: =D5*10% -> 13000 | D6: =E5*10% -> 13500 | E6: =F5*10% -> 14000 | F6: =G5*10% -> 14500 | G6: =H5*10% -> 15500 | H6: =I5*10% -> 16500 | I6: =J5*10% -> 18000 | ... M6: =N5*10% -> 0
A7: Total Requirements | B7: =SUM(B5:B6) -> 132500 | C7: =SUM(C5:C6) -> 138000 | D7: =SUM(D5:D6) -> 143500 | E7: =SUM(E5:E6) -> 149000 | F7: =SUM(F5:F6) -> 154500 | G7: =SUM(G5:G6) -> 160500 | H7: =SUM(H5:H6) -> 171500 | I7: =SUM(I5:I6) -> 183000 | ... M7: =SUM(M5:M6) -> 175000
A8: Less: Opening FG Inventory | C8: =B6 -> 12500 | D8: =C6 -> 13000 | E8: =D6 -> 13500 | F8: =E6 -> 14000 | G8: =F6 -> 14500 | H8: =G6 -> 15500 | I8: =H6 -> 16500 | J8: =I6 -> 18000 | ... M8: =L6 -> 17500
A9: Required Production (Units) | B9: =B7-B8 -> 132500 | C9: =C7-C8 -> 125500 | D9: =D7-D8 -> 130500 | E9: =E7-E8 -> 135500 | F9: =F7-F8 -> 140500 | G9: =G7-G8 -> 146000 | H9: =H7-H8 -> 156000 | I9: =I7-I8 -> 166500 | ... M9: =M7-M8 -> 157500
A10: Capacity utilization | B10: =B9/200000 -> 0.6625 | C10: =C9/200000 -> 0.6275 | D10: =D9/200000 -> 0.6525 | E10: =E9/200000 -> 0.6775 | F10: =F9/200000 -> 0.7025 | G10: =G9/200000 -> 0.73 | H10: =H9/200000 -> 0.78 | I10: =I9/200000 -> 0.8325 | ... M10: =M9/200000 -> 0.7875

Sheet Materials Budget
A1: Materials Budget
A3: Particulars | B3: Apr | C3: May | D3: Jun | E3: Jul | F3: Aug | G3: Sep | H3: Oct | I3: Nov | J3: Dec | K3: Jan | L3: Feb | M3: Mar
A4: Production (Units) | B4: ='Production Budget'!B9 -> 132500 | C4: ='Production Budget'!C9 -> 125500 | D4: ='Production Budget'!D9 -> 130500 | E4: ='Production Budget'!E9 -> 135500 | F4: ='Production Budget'!F9 -> 140500 | G4: ='Production Budget'!G9 -> 146000 | H4: ='Production Budget'!H9 -> 156000 | I4: ='Production Budget'!I9 -> 166500 | ... M4: ='Production Budget'!M9 -> 157500
A5: Aluminium per Unit (kg) | B5: 0.38 | C5: 0.38 | D5: 0.38 | E5: 0.38 | F5: 0.38 | G5: 0.38 | H5: 0.38 | I5: 0.38 | J5: 0.38 | K5: 0.38 | L5: 0.38 | M5: 0.38
A6: Basic Aluminium Requirement (kg) | B6: =B4*B5 -> 50350 | C6: =C4*C5 -> 47690 | D6: =D4*D5 -> 49590 | E6: =E4*E5 -> 51490 | F6: =F4*F5 -> 53390 | G6: =G4*G5 -> 55480 | H6: =H4*H5 -> 59280 | I6: =I4*I5 -> 63270 | ... M6: =M4*M5 -> 59850
A7: Add: Production Loss (2%) | B7: =B6*2% -> 1007 | C7: =C6*2% -> 953.8 | D7: =D6*2% -> 991.8 | E7: =E6*2% -> 1029.8 | F7: =F6*2% -> 1067.8 | G7: =G6*2% -> 1109.6 | H7: =H6*2% -> 1185.6 | I7: =I6*2% -> 1265.4 | ... M7: =M6*2% -> 1197
A8: Total Aluminium Requirement (kg) | B8: =SUM(B6:B7) -> 51357 | C8: =SUM(C6:C7) -> 48643.8 | D8: =SUM(D6:D7) -> 50581.8 | E8: =SUM(E6:E7) -> 52519.8 | F8: =SUM(F6:F7) -> 54457.8 | G8: =SUM(G6:G7) -> 56589.6 | H8: =SUM(H6:H7) -> 60465.6 | I8: =SUM(I6:I7) -> 64535.4 | ... M8: =SUM(M6:M7) -> 61047
A10: Particulars | B10: Apr | C10: May | D10: Jun | E10: Jul | F10: Aug | G10: Sep | H10: Oct | I10: Nov | J10: Dec | K10: Jan | L10: Feb | M10: Mar
A11: Material Requirement (kg) | B11: =B8 -> 51357 | C11: =C8 -> 48643.8 | D11: =D8 -> 50581.8 | E11: =E8 -> 52519.8 | F11: =F8 -> 54457.8 | G11: =G8 -> 56589.6 | H11: =H8 -> 60465.6 | I11: =I8 -> 64535.4 | ... M11: =M8 -> 61047
A12: Add: Desired Closing RM Inventory | B12: =C11*15% -> 7296.57 | C12: =D11*15% -> 7587.27 | D12: =E11*15% -> 7877.97 | E12: =F11*15% -> 8168.67 | F12: =G11*15% -> 8488.44 | G12: =H11*15% -> 9069.84 | H12: =I11*15% -> 9680.31 | I12: =J11*15% -> 10407.06 | ... M12: =N11*15% -> 0
A13: Total Material Required | B13: =SUM(B11:B12) -> 58653.57 | C13: =SUM(C11:C12) -> 56231.07 | D13: =SUM(D11:D12) -> 58459.77 | E13: =SUM(E11:E12) -> 60688.47 | F13: =SUM(F11:F12) -> 62946.24 | G13: =SUM(G11:G12) -> 65659.44 | H13: =SUM(H11:H12) -> 70145.91 | I13: =SUM(I11:I12) -> 74942.46 | ... M13: =SUM(M11:M12) -> 61047
A14: Less: Opening RM Inventory | B14: 8000 | C14: =B12 -> 7296.57 | D14: =C12 -> 7587.27 | E14: =D12 -> 7877.97 | F14: =E12 -> 8168.67 | G14: =F12 -> 8488.44 | H14: =G12 -> 9069.84 | I14: =H12 -> 9680.31 | J14: =I12 -> 10407.06 | ... M14: =L12 -> 9157.05
A15: Material Purchases (kg) | B15: =B13-B14 -> 50653.57 | C15: =C13-C14 -> 48934.5 | D15: =D13-D14 -> 50872.5 | E15: =E13-E14 -> 52810.5 | F15: =F13-F14 -> 54777.57 | G15: =G13-G14 -> 57171 | H15: =H13-H14 -> 61076.07 | I15: =I13-I14 -> 65262.15 | ... M15: =M13-M14 -> 51889.95
A16: Material Purchases (in tonnes) | B16: =B15/1000 -> 50.65357 | C16: =C15/1000 -> 48.9345 | D16: =D15/1000 -> 50.8725 | E16: =E15/1000 -> 52.8105 | F16: =F15/1000 -> 54.77757 | G16: =G15/1000 -> 57.171 | H16: =H15/1000 -> 61.07607 | I16: =I15/1000 -> 65.26215 | ... M16: =M15/1000 -> 51.88995

Sheet Data insights
A1: Aluminium Price Data Insights
A3: Month data
A6: Statistics
A7: Mean | B7: 0.0005339498
A8: Standard Error | B8: 0.00042849094
A9: Median | B9: 0
A10: Mode | B10: -0.0025
A11: Standard Deviation | B11: 0.011789342
A12: Standard Deviation (annualised) | B12: =B11*SQRT(252) -> 0.18715001
A13: Sample Variance | B13: 0.00013898859
A14: Kurtosis | B14: 1.3545018
A15: Skewness | B15: 0.27185202
A16: Range | B16: 0.1036
A17: Minimum | B17: -0.0507
A18: Maximum | B18: 0.0529
A19: Sum | B19: 0.4042
A20: Count | B20: 757
A22: Month | B22: 2023 | C22: 2024 | D22: 2025 | E22: 2026 | F22: Grand Total
A23: Jan | C23: -0.055788591 | D23: 0.0087314017 | E23: 0.011058847 | F23: -0.035998342
A24: Feb | C24: -0.011550422 | D24: 0.011799868 | E24: 0.065132393 | F24: 0.065381839
A25: Mar | C25: 0.065168539 | D25: -0.02604826 | E25: 0.06627635 | F25: 0.10539663
A26: Apr | B26: -0.0288 | C26: 0.085232068 | D26: -0.054848747 | F26: 0.0015833201
A27: May | B27: -0.042372881 | C27: 0.038880249 | D27: 0.013773416 | F27: 0.010280783
A28: Jun | B28: -0.046460177 | C28: -0.051272455 | D28: 0.071733947 | F28: -0.025998685
A29: Jul | B29: 0.049651972 | C29: -0.085996055 | D29: -0.013693376 | F29: -0.050037459
A30: Aug | B30: -0.011494253 | C30: 0.059128183 | D30: 0.015322392 | F30: 0.062956323
A31: Sep | B31: 0.038908766 | C31: 0.059494703 | D31: 0.03096752 | F31: 0.12937099
A32: Oct | B32: -0.032716315 | C32: 0.010384615 | D32: 0.080043839 | F32: 0.05771214
A33: Nov | B33: -0.02670227 | C33: -0.0098972212 | D33: -0.00990678 | F33: -0.046506271
A34: Dec | B34: 0.090077732 | C34: -0.018069973 | D34: 0.041448077 | F34: 0.11345584
A35: Grand Total | B35: -0.0099074262 | C35: 0.085713639 | D35: 0.1693233 | E35: 0.14246759 | F35: 0.3875971

Sheet Price prediction
A1: Price predictions
A5: Forecast | N5: Actuals
A6: Weight | B6: Month | C6: Regression forecast | E6: 3 month moving avg | G6: 6 month moving avg | N6: Weight | O6: Month | P6: Close | Q6: Change %
C7: Open | D7: Change % | E7: Open | F7: Change % | G7: Open | H7: Change % | N7: 1 | O7: 45017 | P7: 2360 | Q7: -0.0288
A8: 37 | B8: 46113 | C8: =FORECAST(A8,P7:P42,N7:N42) -> 2984.3729 | D8: =(C8-P42)/P42 -> -0.13297904 | E8: =(P40+P41+P42)/3 -> 3233.6667 | F8: =(E8-P42)/P42 -> -0.060554119 | G8: 3025.0929 | H8: =(G8-P42)/P42 -> -0.12114905 | J8: Last close | K8: =P42 -> 3442.1 | N8: 2 | O8: 45047 | P8: 2260 | Q8: -0.042372881
A9: 38 | B9: 46143 | C9: =FORECAST(A9,P8:P42,N8:N42) -> 3023.16 | D9: =(C9-C8)/C8 -> 0.012996748 | E9: =(P41+P42+E8)/3 -> 3301.3056 | F9: =(E9-E8)/E8 -> 0.020917088 | G9: 3072.7276 | H9: =(G9-G8)/G8 -> 0.015746523 | J9: S.D | K9: =_xlfn.STDEV.P(P7:P42) -> 291.93819 | N9: 3 | O9: 45078 | P9: 2155 | Q9: -0.046460177
A10: 39 | B10: 46174 | C10: =FORECAST(A10,P9:P42,N9:N42) -> 3057.4862 | D10: =(C10-C9)/C9 -> 0.011354407 | E10: =(P42+E8+E9)/3 -> 3325.6907 | F10: =(E10-E9)/E9 -> 0.0073865278 | G10: 3096.3886 | H10: =(G10-G9)/G9 -> 0.0077003504 | N10: 4 | O10: 45108 | P10: 2262 | Q10: 0.049651972
A11: 40 | B11: 46204 | C11: =FORECAST(A11,P10:P42,N10:N42) -> 3084.0204 | D11: =(C11-C10)/C10 -> 0.0086784292 | E11: =(E8+E9+E10)/3 -> 3286.8877 | F11: =(E11-E10)/E10 -> -0.011667677 | G11: 3127.5441 | H11: =(G11-G10)/G10 -> 0.010061889 | J11: Upper Range (1 SD) | K11: =K8+K9 -> 3734.0382 | L11: =(K11-$K$8)/$K$8 -> 0.084813977 | N11: 5 | O11: 45139 | P11: 2236 | Q11: -0.011494253
A12: 41 | B12: 46235 | C12: =FORECAST(A12,P11:P42,N11:N42) -> 3118.4662 | D12: =(C12-C11)/C11 -> 0.01116914 | E12: =(E9+E10+E11)/3 -> 3304.628 | F12: =(E12-E11)/E11 -> 0.0053973032 | G12: 3146.1076 | H12: =(G12-G11)/G11 -> 0.0059354717 | J12: Lower Range (1 SD) | K12: =K8-K9 -> 3150.1618 | L12: =(K12-$K$8)/$K$8 -> -0.084813977 | N12: 6 | O12: 45170 | P12: 2323 | Q12: 0.038908766
A13: 42 | B13: 46266 | C13: =FORECAST(A13,P12:P42,N12:N42) -> 3150.431 | D13: =(C13-C12)/C12 -> 0.01025015 | E13: =(E10+E11+E12)/3 -> 3305.7355 | F13: =(E13-E12)/E12 -> 0.0003351288 | G13: 3162.5873 | H13: =(G13-G12)/G12 -> 0.0052381097 | J13: Upper Range (2 SD) | K13: =K8+2*K9 -> 4025.9764 | L13: =(K13-$K$8)/$K$8 -> 0.16962795 | N13: 7 | O13: 45200 | P13: 2247 | Q13: -0.032716315
A14: 43 | B14: 46296 | C14: =FORECAST(A14,P13:P42,N13:N42) -> 3191.2736 | D14: =(C14-C13)/C13 -> 0.012964146 | E14: =(E11+E12+E13)/3 -> 3299.0837 | F14: =(E14-E13)/E13 -> -0.0020121878 | G14: 3153.2211 | H14: =(G14-G13)/G13 -> -0.002961533 | J14: Lower Range (2 SD) | K14: =K8-2*K9 -> 2858.2236 | L14: =(K14-$K$8)/$K$8 -> -0.16962795 | N14: 8 | O14: 45231 | P14: 2187 | Q14: -0.02670227
A15: 44 | B15: 46327 | C15: =FORECAST(A15,P14:P42,N14:N42) -> 3223.6368 | D15: =(C15-C14)/C14 -> 0.010141165 | E15: =(E12+E13+E14)/3 -> 3303.149 | F15: =(E15-E14)/E14 -> 0.0012322659 | G15: 3111.9527 | H15: =(G15-G14)/G14 -> -0.013087698 | N15: 9 | O15: 45261 | P15: 2384 | Q15: 0.090077732
A16: 45 | B16: 46357 | C16: =FORECAST(A16,P15:P42,N15:N42) -> 3245.1732 | D16: =(C16-C15)/C15 -> 0.006680748 | E16: =(E13+E14+E15)/3 -> 3302.6561 | F16: =(E16-E15)/E15 -> -0.00014924507 | G16: 3124.3613 | H16: =(G16-G15)/G15 -> 0.0039873854 | N16: 10 | O16: 45292 | P16: 2251 | Q16: -0.055788591
A17: 46 | B17: 46388 | C17: =FORECAST(A17,P16:P42,N16:N42) -> 3291.7169 | D17: =(C17-C16)/C16 -> 0.014342451 | E17: =(E14+E15+E16)/3 -> 3301.6296 | F17: =(E17-E16)/E16 -> -0.00031079943 | G17: 3131.7375 | H17: =(G17-G16)/G16 -> 0.0023608823 | N17: 11 | O17: 45323 | P17: 2225 | Q17: -0.011550422
A18: 47 | B18: 46419 | C18: =FORECAST(A18,P17:P42,N17:N42) -> 3316.1672 | D18: =(C18-C17)/C17 -> 0.0074278329 | E18: =(E15+E16+E17)/3 -> 3302.4782 | F18: =(E18-E17)/E17 -> 0.00025703529 | G18: 3136.7874 | H18: =(G18-G17)/G17 -> 0.0016124739 | N18: 12 | O18: 45352 | P18: 2370 | Q18: 0.065168539
A19: 48 | B19: 46447 | C19: =FORECAST(A19,P18:P42,N18:N42) -> 3328.4255 | D19: =(C19-C18)/C18 -> 0.003696534 | E19: =(E16+E17+E18)/3 -> 3302.2546 | F19: =(E19-E18)/E18 -> -6.7707437e-05 | G19: 3138.1079 | H19: =(G19-G18)/G18 -> 0.00042096036 | N19: 13 | O19: 45383 | P19: 2572 | Q19: 0.085232068
N20: 14 | O20: 45413 | P20: 2672 | Q20: 0.038880249
N21: 15 | O21: 45444 | P21: 2535 | Q21: -0.051272455
N22: 16 | O22: 45474 | P22: 2317 | Q22: -0.085996055
N23: 17 | O23: 45505 | P23: 2454 | Q23: 0.059128183
N24: 18 | O24: 45536 | P24: 2600 | Q24: 0.059494703
N25: 19 | O25: 45566 | P25: 2627 | Q25: 0.010384615
N26: 20 | O26: 45597 | P26: 2601 | Q26: -0.0098972212
N27: 21 | O27: 45627 | P27: 2554 | Q27: -0.018069973
N28: 22 | O28: 45658 | P28: 2576.3 | Q28: 0.0087314017
N29: 23 | O29: 45689 | P29: 2606.7 | Q29: 0.011799868
N30: 24 | O30: 45717 | P30: 2538.8 | Q30: -0.02604826
N31: 25 | O31: 45748 | P31: 2399.55 | Q31: -0.054848747
... N42: 36 | O42: 46082 | P42: 3442.1 | Q42: 0.06627635

Sheet Hedging analysis
A1: Initial Hedging Budget and Details
A4: Particulars | B4: 46113 | C4: 46143 | D4: 46174 | E4: 46204 | F4: 46235 | G4: 46266 | H4: 46296 | I4: 46327 | J4: 46357 | K4: 46388 | L4: 46419 | M4: 46447
A5: Material Purchases (in tonnes) | B5: 50.65357 | C5: 48.9345 | D5: 50.8725 | E5: 52.8105 | F5: 54.77757 | G5: 57.171 | H5: 61.07607 | I5: 65.26215 | J5: 68.799 | K5: 65.06835 | L5: 62.36484 | M5: 51.88995
A6: Contract Size (in tonnes) | B6: 25 | C6: 25 | D6: 25 | E6: 25 | F6: 25 | G6: 25 | H6: 25 | I6: 25 | J6: 25 | K6: 25 | L6: 25 | M6: 25
A7: Hedge % | B7: 1 | C7: 1 | D7: 1 | E7: 1 | F7: 1 | G7: 1 | H7: 1 | I7: 1 | J7: 1 | K7: 1 | L7: 1 | M7: 1
A8: Hedge quantity (in tonnes) | B8: =B5*B7 -> 50.65357 | C8: =C5*C7 -> 48.9345 | D8: =D5*D7 -> 50.8725 | E8: =E5*E7 -> 52.8105 | F8: =F5*F7 -> 54.77757 | G8: =G5*G7 -> 57.171 | H8: =H5*H7 -> 61.07607 | I8: =I5*I7 -> 65.26215 | ... M8: =M5*M7 -> 51.88995
A9: No of contracts | B9: =B8/B6 -> 2.0261428 | C9: =C8/C6 -> 1.95738 | D9: =D8/D6 -> 2.0349 | E9: =E8/E6 -> 2.11242 | F9: =F8/F6 -> 2.1911028 | G9: =G8/G6 -> 2.28684 | H9: =H8/H6 -> 2.4430428 | I9: =I8/I6 -> 2.610486 | ... M9: =M8/M6 -> 2.075598
A10: Rounded off | B10: =ROUND(B9,0) -> 2 | C10: =ROUND(C9,0) -> 2 | D10: =ROUND(D9,0) -> 2 | E10: =ROUND(E9,0) -> 2 | F10: =ROUND(F9,0) -> 2 | G10: =ROUND(G9,0) -> 2 | H10: =ROUND(H9,0) -> 2 | I10: =ROUND(I9,0) -> 3 | ... M10: =ROUND(M9,0) -> 2
A11: Under/Over Hedging | B11: =IF(B10>B9, "Over Hedged","Under Hedged") -> Under Hedged | C11: =IF(C10>C9, "Over Hedged","Under Hedged") -> Over Hedged | D11: =IF(D10>D9, "Over Hedged","Under Hedged") -> Under Hedged | E11: =IF(E10>E9, "Over Hedged","Under Hedged") -> Under Hedged | F11: =IF(F10>F9, "Over Hedged","Under Hedged") -> Under Hedged | G11: =IF(G10>G9, "Over Hedged","Under Hedged") -> Under Hedged | H11: =IF(H10>H9, "Over Hedged","Under Hedged") -> Under Hedged | I11: =IF(I10>I9, "Over Hedged","Under Hedged") -> Over Hedged | ... M11: =IF(M10>M9, "Over Hedged","Under Hedged") -> Under Hedged
A14: Parameter | B14: Specification
A15: Contract Name | B15: LME Aluminium Futures Contract
A16: Underlying Asset | B16: Primary Aluminium
A17: Exchange | B17: London Metal Exchange (LME)
A18: Contract Size | B18: 25 Metric Tonnes (MT)
A19: Contract Type | B19: Futures Contract
A20: Position Taken | B20: Long Hedge (Buyer)
A21: Pricing Unit | B21: USD per Metric Tonne (USD/MT)
A22: Settlement Method | B22: Cash Settlement (assumed for this model)
A23: Hedging Horizon | B23: One Month Ahead
A24: Contract Expiry | B24: Matching Purchase Month
A25: Hedge Ratio | B25: 100% of Forecast Aluminium Requirement
... A29: Purpose | B29: To hedge aluminium price risk arising
B30: from raw material purchases

Sheet Actuals
A1: Actual results
A3: Particulars | B3: Apr | C3: May | D3: Jun | E3: Q1 Total | G3: Date | H3: Aluminium prices
A4: Actual Production (Rolls) | B4: 129200 | C4: 134500 | D4: 138700 | E4: 402400 | G4: 46082 | H4: 3194
A5: Actual Aluminium Used (kg) | B5: 50430 | C5: 52550 | D5: 54180 | E5: 157160 | G5: 46112 | H5: 3429
A6: Actual Purchases (kg) | B6: 51800 | C6: 53200 | D6: 54600 | E6: 159600 | G6: 46113 | H6: 3523
A7: Actual Avg Price (USD/t) | B7: 3480 | C7: 3530 | D7: 3725 | E7: =AVERAGE(B7:D7) -> 3578.3333 | G7: 46142 | H7: 3483
A8: Expected budgeted price | B8: 3194 | C8: 3523 | D8: 3518 | G8: 46143 | H8: 3518
G9: 46173 | H9: 3675
G10: 46174 | H10: 3731
G11: 46203 | H11: 3098
A16: Note : Previous month first day price is taken as the budgeted price for the next month as hedging position taken for the month at that time

Sheet Budget vs Actuals
A1: Budget vs Actual - Variance analysis
A4: Particulars | B4: Actual | E4: Budgeted
B5: Apr | C5: May | D5: Jun | E5: Apr | F5: May | G5: Jun
A6: Total Aluminium Requirement (in tonnes) | B6: 51.357 | C6: 48.6438 | D6: 50.5818 | E6: =Actuals!B5/1000 -> 50.43 | F6: =Actuals!C5/1000 -> 52.55 | G6: =Actuals!D5/1000 -> 54.18
A7: Material Purchase (in tonnes) | B7: =Actuals!B6/1000 -> 51.8 | C7: =Actuals!C6/1000 -> 53.2 | D7: =Actuals!D6/1000 -> 54.6 | E7: ='Materials Budget'!B16 -> 50.65357 | F7: ='Materials Budget'!C16 -> 48.9345 | G7: ='Materials Budget'!D16 -> 50.8725
A8: Avg Cost per tonne | B8: =Actuals!B7 -> 3480 | C8: =Actuals!C7 -> 3530 | D8: =Actuals!D7 -> 3725 | E8: =Actuals!B8 -> 3194 | F8: =Actuals!C8 -> 3523 | G8: =Actuals!D8 -> 3518
A9: Total Material Cost | B9: =B7*B8 -> 180264 | C9: =C7*C8 -> 187796 | D9: =D7*D8 -> 203385 | E9: =E7*E8 -> 161787.5 | F9: =F7*F8 -> 172396.24 | G9: =G7*G8 -> 178969.46
A13: Particulars | B13: Variance amount | E13: Variance %
B14: Apr | C14: May | D14: Jun | E14: Apr | F14: May | G14: Jun
A15: Total Aluminium Requirement (in tonnes) | B15: =E6-B6 -> -0.927 | C15: =F6-C6 -> 3.9062 | D15: =G6-D6 -> 3.5982 | E15: =B15/E6 -> -0.018381916 | F15: =C15/F6 -> 0.074333016 | G15: =D15/G6 -> 0.06641196
A16: Material Purchase (in tonnes) | B16: =E7-B7 -> -1.14643 | C16: =F7-C7 -> -4.2655 | D16: =G7-D7 -> -3.7275 | E16: =B16/E7 -> -0.022632758 | F16: =C16/F7 -> -0.08716754 | G16: =D16/G7 -> -0.073271414
A17: Budgeted Cost per tonne | B17: =E8-B8 -> -286 | C17: =F8-C8 -> -7 | D17: =G8-D8 -> -207 | E17: =B17/E8 -> -0.089542893 | F17: =C17/F8 -> -0.0019869429 | G17: =D17/G8 -> -0.05884025
A18: Total Material Cost | B18: =E9-B9 -> -18476.497 | C18: =F9-C9 -> -15399.756 | D18: =G9-D9 -> -24415.545 | E18: =B18/E9 -> -0.11420225 | F18: =C18/F9 -> -0.08932768 | G18: =D18/G9 -> -0.13642297
A20: Particulars | B20: Apr | C20: May | D20: Jun
A21: Standard cost for actual material quantity | B21: =E8*B7 -> 165449.2 | C21: =F8*C7 -> 187423.6 | D21: =G8*D7 -> 192082.8
A22: Variance with standard cost | B22: =B21-B9 -> -14814.8 | C22: =C21-C9 -> -372.4 | D22: =D21-D9 -> -11302.2

Sheet Hedging results
A1: Hedging Review
A3: Month | B3: Hedge for | C3: Buy price | D3: Sell price | E3: Contracts | F3: Buy value | G3: Sell Value | H3: Profit/Loss
A4: Mar | B4: Apr | C4: 3194 | D4: 3429 | E4: 2 | F4: =C4*25*E4 -> 159700 | G4: =D4*25*E4 -> 171450 | H4: =G4-F4 -> 11750
A5: Apr | B5: May | C5: =Actuals!H6 -> 3523 | D5: =Actuals!H7 -> 3483 | E5: ='Hedging analysis'!B10 -> 2 | F5: =C5*25*E5 -> 176150 | G5: =D5*25*E5 -> 174150 | H5: =G5-F5 -> -2000
A6: May | B6: Jun | C6: =Actuals!H8 -> 3518 | D6: =Actuals!H9 -> 3675 | E6: ='Hedging analysis'!C10 -> 2 | F6: =C6*25*E6 -> 175900 | G6: =D6*25*E6 -> 183750 | H6: =G6-F6 -> 7850
A7: Jun | B7: July | C7: =Actuals!H10 -> 3731 | D7: =Actuals!H11 -> 3098 | E7: ='Hedging analysis'!D10 -> 2 | F7: =C7*25*E7 -> 186550 | G7: =D7*25*E7 -> 154900 | H7: =G7-F7 -> -31650
A9: Month | B9: Profit/Loss | C9: MPV (Std) | D9: Net P&L | E9: MPV (A) | F9: Net P&L
A10: Apr | B10: =H4 -> 11750 | C10: ='Budget vs Actuals'!B22 -> -14814.8 | D10: =B10+C10 -> -3064.8 | E10: ='Budget vs Actuals'!B18 -> -18476.497 | F10: =B10+E10 -> -6726.4974
A11: May | B11: =H5 -> -2000 | C11: ='Budget vs Actuals'!C22 -> -372.4 | D11: =B11+C11 -> -2372.4 | E11: ='Budget vs Actuals'!C18 -> -15399.756 | F11: =B11+E11 -> -17399.756
A12: Jun | B12: =H6 -> 7850 | C12: ='Budget vs Actuals'!D22 -> -11302.2 | D12: =B12+C12 -> -3452.2 | E12: ='Budget vs Actuals'!D18 -> -24415.545 | F12: =B12+E12 -> -16565.545
A13: Total | B13: =SUM(B10:B12) -> 17600 | C13: =SUM(C10:C12) -> -26489.4 | D13: =SUM(D10:D12) -> -8889.4 | E13: =SUM(E10:E12) -> -58291.799 | F13: =SUM(F10:F12) -> -40691.799
A16: *We hedge for the next month purchase in the current month contract so we can purchase next month requirement at the start

Sheet Aluminium Historical workings
A1: Date | B1: Price | C1: Change % | L1: Date | M1: Month | N1: Open | O1: Change %
A2: 45019 | B2: 2397.5 | C2: -0.0064 | E2: Sum of Change % | F2: Column Labels | L2: 45046 | M2: 45017 | N2: 2360 | O2: -0.0288 | P2: 2547 | Q2: Sum of Change % | R2: Column Labels
A3: 45020 | B3: 2370.5 | C3: -0.0113 | E3: Row Labels | F3: 2023 | G3: 2024 | H3: 2025 | I3: 2026 | J3: Grand Total | L3: 45077 | M3: 45047 | N3: 2260 | O3: -0.042372881 | P3: 2547 | Q3: Row Labels | R3: 2023 | S3: 2024 | T3: 2025 | U3: 2026 | V3: Grand Total
A4: 45021 | B4: 2333.5 | C4: -0.0156 | E4: Jan | G4: -0.0432 | H4: 0.0183 | I4: 0.0418 | J4: 0.0169 | L4: 45107 | M4: 45078 | N4: 2155 | O4: -0.046460177 | P4: 2547 | Q4: Jan | S4: -0.055788591 | T4: 0.0087314017 | U4: 0.011058847 | V4: -0.035998342
A5: 45022 | B5: 2333.5 | C5: 0 | E5: Feb | G5: -0.0225 | H5: 0.0057 | I5: 0.0107 | J5: -0.0061 | L5: 45138 | M5: 45108 | N5: 2262 | O5: 0.049651972 | P5: 2547 | Q5: Feb | S5: -0.011550422 | T5: 0.011799868 | U5: 0.065132393 | V5: 0.065381839
A6: 45027 | B6: 2302.5 | C6: -0.0133 | E6: Mar | G6: 0.0484 | H6: -0.0267 | I6: 0.0913 | J6: 0.113 | L6: 45169 | M6: 45139 | N6: 2236 | O6: -0.011494253 | P6: 2547 | Q6: Mar | S6: 0.065168539 | T6: -0.02604826 | U6: 0.06627635 | V6: 0.10539663
A7: 45028 | B7: 2325 | C7: 0.0098 | E7: Apr | F7: -0.0224 | G7: 0.1054 | H7: -0.0546 | J7: 0.0284 | L7: 45199 | M7: 45170 | N7: 2323 | O7: 0.038908766 | P7: 2547 | Q7: Apr | R7: -0.0288 | S7: 0.085232068 | T7: -0.054848747 | V7: 0.0015833201
A8: 45029 | B8: 2367 | C8: 0.0181 | E8: May | F8: -0.0461 | G8: 0.026 | H8: 0.0214 | J8: 0.0013 | L8: 45230 | M8: 45200 | N8: 2247 | O8: -0.032716315 | P8: 2547 | Q8: May | R8: -0.042372881 | S8: 0.038880249 | T8: 0.013773416 | V8: 0.010280783
A9: 45030 | B9: 2385.5 | C9: 0.0078 | E9: Jun | F9: -0.0415 | G9: -0.0485 | H9: 0.0622 | J9: -0.0278 | L9: 45260 | M9: 45231 | N9: 2187 | O9: -0.02670227 | P9: 2547 | Q9: Jun | R9: -0.046460177 | S9: -0.051272455 | T9: 0.071733947 | V9: -0.025998685
A10: 45033 | B10: 2378.5 | C10: -0.0029 | E10: Jul | F10: 0.0608 | G10: -0.0956 | H10: -0.0134 | J10: -0.0482 | L10: 45291 | M10: 45261 | N10: 2384 | O10: 0.090077732 | P10: 2547 | Q10: Jul | R10: 0.049651972 | S10: -0.085996055 | T10: -0.013693376 | V10: -0.050037459
A11: 45034 | B11: 2437 | C11: 0.0246 | E11: Aug | F11: -0.0321 | G11: 0.068 | H11: 0.0218 | J11: 0.0577 | L11: 45322 | M11: 45292 | N11: 2251 | O11: -0.055788591 | P11: 2547 | Q11: Aug | R11: -0.011494253 | S11: 0.059128183 | T11: 0.015322392 | V11: 0.062956323
A12: 45035 | B12: 2445 | C12: 0.0033 | E12: Sep | F12: 0.0626 | G12: 0.0675 | H12: 0.0239 | J12: 0.154 | L12: 45351 | M12: 45323 | N12: 2225 | O12: -0.011550422 | P12: 2547 | Q12: Sep | R12: 0.038908766 | S12: 0.059494703 | T12: 0.03096752 | V12: 0.12937099
A13: 45036 | B13: 2421 | C13: -0.0098 | E13: Oct | F13: -0.0405 | G13: 0.0046 | H13: 0.0764 | J13: 0.0405 | L13: 45382 | M13: 45352 | N13: 2370 | O13: 0.065168539 | P13: 2547 | Q13: Oct | R13: -0.032716315 | S13: 0.010384615 | T13: 0.080043839 | V13: 0.05771214
A14: 45037 | B14: 2396.5 | C14: -0.0101 | E14: Nov | F14: -0.0256 | G14: -0.0059 | H14: -0.0059 | J14: -0.0374 | L14: 45412 | M14: 45383 | N14: 2572 | O14: 0.085232068 | P14: 2547 | Q14: Nov | R14: -0.02670227 | S14: -0.0098972212 | T14: -0.00990678 | V14: -0.046506271
A15: 45040 | B15: 2381 | C15: -0.0065 | E15: Dec | F15: 0.0856 | G15: -0.016 | H15: 0.0423 | J15: 0.1119 | L15: 45443 | M15: 45413 | N15: 2672 | O15: 0.038880249 | P15: 2547 | Q15: Dec | R15: 0.090077732 | S15: -0.018069973 | T15: 0.041448077 | V15: 0.11345584
A16: 45041 | B16: 2335.5 | C16: -0.0191 | E16: Grand Total | F16: 0.0008 | G16: 0.0882 | H16: 0.1714 | I16: 0.1438 | J16: 0.4042 | L16: 45473 | M16: 45444 | N16: 2535 | O16: -0.051272455 | P16: 2547 | Q16: Grand Total | R16: -0.0099074262 | S16: 0.085713639 | T16: 0.1693233 | U16: 0.14246759 | V16: 0.3875971
A17: 45042 | B17: 2327 | C17: -0.0036 | L17: 45504 | M17: 45474 | N17: 2317 | O17: -0.085996055 | P17: 2547
A18: 45043 | B18: 2319 | C18: -0.0034 | L18: 45535 | M18: 45505 | N18: 2454 | O18: 0.059128183 | P18: 2547
A19: 45044 | B19: 2356 | C19: 0.016 | L19: 45565 | M19: 45536 | N19: 2600 | O19: 0.059494703 | P19: 2547
A20: 45048 | B20: 2366.5 | C20: 0.0045 | L20: 45596 | M20: 45566 | N20: 2627 | O20: 0.010384615 | P20: 2547
A21: 45049 | B21: 2321 | C21: -0.0192 | L21: 45626 | M21: 45597 | N21: 2601 | O21: -0.0098972212 | P21: 2547
A22: 45050 | B22: 2287 | C22: -0.0146 | L22: 45657 | M22: 45627 | N22: 2554 | O22: -0.018069973 | P22: 2547
A23: 45051 | B23: 2318.5 | C23: 0.0138 | L23: 45688 | M23: 45658 | N23: 2576.3 | O23: 0.0087314017 | P23: 2547
A24: 45055 | B24: 2320 | C24: 0.0006 | L24: 45716 | M24: 45689 | N24: 2606.7 | O24: 0.011799868 | P24: 2547
A25: 45056 | B25: 2268 | C25: -0.0224 | L25: 45747 | M25: 45717 | N25: 2538.8 | O25: -0.02604826 | P25: 2547
A26: 45057 | B26: 2211 | C26: -0.0251 | L26: 45777 | M26: 45748 | N26: 2399.55 | O26: -0.054848747 | P26: 2547
A27: 45058 | B27: 2231.5 | C27: 0.0093 | L27: 45808 | M27: 45778 | N27: 2432.6 | O27: 0.013773416 | P27: 2547
A28: 45061 | B28: 2259.5 | C28: 0.0125 | L28: 45838 | M28: 45809 | N28: 2607.1 | O28: 0.071733947 | P28: 2547
... A37: 45072 | B37: 2237.5 | C37: 0.0029 | L37: 46112 | M37: 46082 | N37: 3442.1 | O37: 0.06627635 | P37: 2547
A38: 45076 | B38: 2224 | C38: -0.006
A39: 45077 | B39: 2246 | C39: 0.0099
A40: 45078 | B40: 2282.5 | C40: 0.0163
A41: 45079 | B41: 2263.5 | C41: -0.0083
A42: 45082 | B42: 2244 | C42: -0.0086
A43: 45083 | B43: 2210 | C43: -0.0152
A44: 45084 | B44: 2219 | C44: 0.0041
A45: 45085 | B45: 2254.5 | C45: 0.016
A46: 45086 | B46: 2268 | C46: 0.006
A47: 45089 | B47: 2228 | C47: -0.0176
A48: 45090 | B48: 2232 | C48: 0.0018
...
